Workbook
Name CASE: '[1]Operating Model'!#REF!
Name CIRC: '[1]Operating Model'!#REF!
Name INPUTS: #REF!
Name IQ_CH: 110000
Name IQ_CQ: 5000
Name IQ_CY: 10000
Name IQ_DAILY: 500000
Name IQ_FH: 100000
Name IQ_FQ: 500
Name IQ_FY: 1000
Name IQ_LTM: 2000
Name IQ_MONTH: 15000
Name IQ_NTM: 6000
Name IQ_WEEK: 50000
Name IQ_YTD: 3000
Name METRICS: #REF!
Name PIK: [2]LBO!$E$8
Name REFRESHDATE: #REF!
Name tgr: '[1]Operating Model'!$L$11
Name wacc: '[1]Operating Model'!$L$10

Sheet Cover
D12: Worksheet Tabs:
D13: Ânima's Intrinsic Valuation Methods | E13: Ânima's Market Valuation Methods | F13: Digital Learning Segment Valuation & M&A
D14: Financial Statement Model | E14: Higher Education Peers Data | F14: DL Model & DCF
D15: WACC | E15: Trading Comps | F15: DL Trading Comps
D16: Beta | E16: Transaction Comps | F16: DL Transaction Comps
D17: DCF | F17: Vitru Accretion Dilution
F23: Color Coding:
C24: Last Update: 31/01/2026 | F24: Input | G24: Example
C25: Units of Measurement: R$ Thousands ('000) Except per Share Data | F25: Formula | G25: Example
C26: UFFinance Group: Eduardo Guerra, Daniel Coutinho, Bianca Costa e Douglas Galvão | F26: Switch | G26: Example

Sheet Financial Statement Model
B2: =" Financial Statement Model for "&C5 -> Financial Statement Model for Ânima
B3: R$ Thousands ('000) Except per Share Data
B5: Company name | C5: Ânima
B6: Ticker | C6: ANIM3
B7: Circuit breaker: | C7: Off
B8: Latest closing share price | C8: ='Higher Education Peers Data'!C10 -> 5.23
B9: Basic Share Count (Thousands) | C9: ='Higher Education Peers Data'!C13 -> 403868.8
B10: Select an operating scenario: | C10: Target
A14: 1. | B14: REVENUE BUILD UP | D14: 2021 | E14: 2022 | F14: 2023 | G14: 2024 | H14: 2025 | I14: 2026 | J14: 2027 | K14: 2028 | L14: 2029 | M14: 2030
B16: Ânima Core
B17: Number of Students | E17: 243349 | F17: 244484 | G17: 205265 | H17: =G17+H18 -> 203765 | I17: =H17+I18 -> 208765 | J17: =I17+J18 -> 216765 | K17: =J17+K18 -> 223765 | L17: =K17+L18 -> 229765 | M17: =L17+M18 -> 235765
B18: Net New Students | E18: - | F18: =F17-E17 -> 1135 | G18: =G17-F17 -> -39219 | H18: =_xlfn.XLOOKUP($C$10,$B$285:$B$287,H285:H287) -> -1500 | I18: =_xlfn.XLOOKUP($C$10,$B$285:$B$287,I285:I287) -> 5000 | J18: =_xlfn.XLOOKUP($C$10,$B$285:$B$287,J285:J287) -> 8000 | K18: =_xlfn.XLOOKUP($C$10,$B$285:$B$287,K285:K287) -> 7000 | L18: =_xlfn.XLOOKUP($C$10,$B$285:$B$287,L285:L287) -> 6000 | M18: =_xlfn.XLOOKUP($C$10,$B$285:$B$287,M285:M287) -> 6000
B20: Average Anual Ticket | E20: =E23/E17 -> 9.2830154 | F20: =F23/F17 -> 9.02534 | G20: =G23/G17 -> 10.261804 | H20: =G20*(1+H21) -> 11.082748 | I20: =H20*(1+I21) -> 11.85854 | J20: =I20*(1+J21) -> 12.570053 | K20: =J20*(1+K21) -> 13.198555 | L20: =K20*(1+L21) -> 13.726497 | M20: =L20*(1+M21) -> 14.275557
B21: Average Anual Ticket Growth Rate | E21: - | F21: =F20/E20-1 -> -0.02775773 | G21: =G20/F20-1 -> 0.13699911 | H21: =_xlfn.XLOOKUP($C$10,$B$290:$B$292,H290:H292) -> 0.08 | I21: =_xlfn.XLOOKUP($C$10,$B$290:$B$292,I290:I292) -> 0.07 | J21: =_xlfn.XLOOKUP($C$10,$B$290:$B$292,J290:J292) -> 0.06 | K21: =_xlfn.XLOOKUP($C$10,$B$290:$B$292,K290:K292) -> 0.05 | L21: =_xlfn.XLOOKUP($C$10,$B$290:$B$292,L290:L292) -> 0.04 | M21: =_xlfn.XLOOKUP($C$10,$B$290:$B$292,M290:M292) -> 0.04
B23: Segment Net Revenue | E23: 2259012.5 | F23: 2206551.2 | G23: 2106389.1 | H23: =H17*H20 -> 2258276.1 | I23: =I17*I20 -> 2475648.1 | J23: =J17*J20 -> 2724747.5 | K23: =K17*K20 -> 2953374.7 | L23: =L17*L20 -> 3153868.7 | M23: =M17*M20 -> 3365676.8
B24: Segment Net Revenue Growth Rate | E24: - | F24: =F23/E23-1 -> -0.023223111 | G24: =G23/F23-1 -> -0.045393062 | H24: =H23/G23-1 -> 0.072107763 | I24: =I23/H23-1 -> 0.096255736 | J24: =J23/I23-1 -> 0.10061984 | K24: =K23/J23-1 -> 0.083907688 | L24: =L23/K23-1 -> 0.067886399 | M24: =M23/L23-1 -> 0.067158183
B27: Digital Learning
B28: Number of Students | E28: 138361 | F28: 151817 | G28: 145228 | H28: =G28+H29 -> 138228 | I28: =H28+I29 -> 133228 | J28: =I28+J29 -> 131228 | K28: =J28+K29 -> 132228 | L28: =K28+L29 -> 135228 | M28: =L28+M29 -> 138228
B29: Net New Students | E29: - | F29: =F28-E28 -> 13456 | G29: =G28-F28 -> -6589 | H29: =_xlfn.XLOOKUP($C$10,$B$295:$B$297,H295:H297) -> -7000 | I29: =_xlfn.XLOOKUP($C$10,$B$295:$B$297,I295:I297) -> -5000 | J29: =_xlfn.XLOOKUP($C$10,$B$295:$B$297,J295:J297) -> -2000 | K29: =_xlfn.XLOOKUP($C$10,$B$295:$B$297,K295:K297) -> 1000 | L29: =_xlfn.XLOOKUP($C$10,$B$295:$B$297,L295:L297) -> 3000 | M29: =_xlfn.XLOOKUP($C$10,$B$295:$B$297,M295:M297) -> 3000
B31: Average Anual Ticket | E31: =E34/E28 -> 1.5856839 | F31: =F34/F28 -> 1.8005043 | G31: =G34/G28 -> 2.0577878 | H31: =G31*(1+H32) -> 2.3047223 | I31: =H31*(1+I32) -> 2.5351945 | J31: =I31*(1+J32) -> 2.7380101 | K31: =J31*(1+K32) -> 2.9022907 | L31: =K31*(1+L32) -> 3.0183823 | M31: =L31*(1+M32) -> 3.1391176
B32: Average Anual Ticket Growth Rate | E32: - | F32: =F31/E31-1 -> 0.13547494 | G32: =G31/F31-1 -> 0.14289522 | H32: =_xlfn.XLOOKUP($C$10,$B$300:$B$302,H300:H302) -> 0.12 | I32: =_xlfn.XLOOKUP($C$10,$B$300:$B$302,I300:I302) -> 0.1 | J32: =_xlfn.XLOOKUP($C$10,$B$300:$B$302,J300:J302) -> 0.08 | K32: =_xlfn.XLOOKUP($C$10,$B$300:$B$302,K300:K302) -> 0.06 | L32: =_xlfn.XLOOKUP($C$10,$B$300:$B$302,L300:L302) -> 0.04 | M32: =_xlfn.XLOOKUP($C$10,$B$300:$B$302,M300:M302) -> 0.04
B34: Segment Net Revenue | E34: 219396.81 | F34: 273347.16 | G34: 298848.4 | H34: =H28*H31 -> 318577.15 | I34: =I28*I31 -> 337758.9 | J34: =J28*J31 -> 359303.59 | K34: =K28*K31 -> 383764.09 | L34: =L28*L31 -> 408169.81 | M34: =M28*M31 -> 433913.95
B35: Segment Net Revenue Growth Rate | E35: - | F35: =F34/E34-1 -> 0.2459031 | G35: =G34/F34-1 -> 0.0932925 | H35: =H34/G34-1 -> 0.06601592 | I35: =I34/H34-1 -> 0.060210666 | J35: =J34/I34-1 -> 0.063787192 | K35: =K34/J34-1 -> 0.068077544 | L35: =L34/K34-1 -> 0.063595608 | M35: =M34/L34-1 -> 0.063072145
B38: Inspirali
B39: Number of Students | E39: 13634 | F39: 14703 | G39: 18767 | H39: =G39+H40 -> 21767 | I39: =H39+I40 -> 25767 | J39: =I39+J40 -> 29267 | K39: =J39+K40 -> 32267 | L39: =K39+L40 -> 34767 | M39: =L39+M40 -> 37267
B40: Net New Students | E40: - | F40: =F39-E39 -> 1069 | G40: =G39-F39 -> 4064 | H40: =_xlfn.XLOOKUP($C$10,$B$305:$B$307,H305:H307) -> 3000 | I40: =_xlfn.XLOOKUP($C$10,$B$305:$B$307,I305:I307) -> 4000 | J40: =_xlfn.XLOOKUP($C$10,$B$305:$B$307,J305:J307) -> 3500 | K40: =_xlfn.XLOOKUP($C$10,$B$305:$B$307,K305:K307) -> 3000 | L40: =_xlfn.XLOOKUP($C$10,$B$305:$B$307,L305:L307) -> 2500 | M40: =_xlfn.XLOOKUP($C$10,$B$305:$B$307,M305:M307) -> 2500
B42: Average Anual Ticket | E42: =E45/E39 -> 79.567317 | F42: =F45/F39 -> 85.223508 | G42: =G45/G39 -> 74.393152 | H42: =G42*(1+H43) -> 77.368878 | I42: =H42*(1+I43) -> 82.397855 | J42: =I42*(1+J43) -> 88.989684 | K42: =J42*(1+K43) -> 95.66391 | L42: =K42*(1+L43) -> 102.36038 | M42: =L42*(1+M43) -> 109.52561
B43: Average Anual Ticket Growth Rate | E43: - | F43: =F42/E42-1 -> 0.071086862 | G43: =G42/F42-1 -> -0.12708179 | H43: =_xlfn.XLOOKUP($C$10,$B$310:$B$312,H310:H312) -> 0.04 | I43: =_xlfn.XLOOKUP($C$10,$B$310:$B$312,I310:I312) -> 0.065 | J43: =_xlfn.XLOOKUP($C$10,$B$310:$B$312,J310:J312) -> 0.08 | K43: =_xlfn.XLOOKUP($C$10,$B$310:$B$312,K310:K312) -> 0.075 | L43: =_xlfn.XLOOKUP($C$10,$B$310:$B$312,L310:L312) -> 0.07 | M43: =_xlfn.XLOOKUP($C$10,$B$310:$B$312,M310:M312) -> 0.07
B45: Segment Net Revenue | E45: 1084820.8 | F45: 1253041.2 | G45: 1396136.3 | H45: =H39*H42 -> 1684088.4 | I45: =I39*I42 -> 2123145.5 | J45: =J39*J42 -> 2604461.1 | K45: =K39*K42 -> 3086787.4 | L45: =L39*L42 -> 3558763.5 | M45: =M39*M42 -> 4081690.9
B46: Segment Net Revenue Growth Rate | E46: - | F46: =F45/E45-1 -> 0.15506749 | G46: =G45/F45-1 -> 0.1141982 | H46: =H45/G45-1 -> 0.20624927 | I46: =I45/H45-1 -> 0.2607091 | J46: =J45/I45-1 -> 0.22669927 | K46: =K45/J45-1 -> 0.18519237 | L46: =L45/K45-1 -> 0.15290204 | M46: =M45/L45-1 -> 0.14694078
B50: Total Number of Students | E50: =E39+E28+E17 -> 395344 | F50: =F39+F28+F17 -> 411004 | G50: =G39+G28+G17 -> 369260 | H50: =H39+H28+H17 -> 363760 | I50: =I39+I28+I17 -> 367760 | J50: =J39+J28+J17 -> 377260 | K50: =K39+K28+K17 -> 388260 | L50: =L39+L28+L17 -> 399760 | M50: =M39+M28+M17 -> 411260
B51: Total Average Anual Ticket | E51: =E52/E50 -> 9.0129865 | F51: =F52/F50 -> 9.0824898 | G51: =G52/G50 -> 10.294572 | H51: =H52/H50 -> 11.713607 | I51: =I52/I50 -> 13.423299 | J51: =J52/J50 -> 15.078493 | K51: =K52/K50 -> 16.545424 | L51: =L52/L50 -> 17.812692 | M51: =M52/M50 -> 19.163745
B52: Total Net Revenue | E52: =SUM(E45,E34,E23) -> 3563230.1 | F52: =SUM(F45,F34,F23) -> 3732939.6 | G52: =SUM(G45,G34,G23) -> 3801373.8 | H52: =SUM(H45,H34,H23) -> 4260941.6 | I52: =SUM(I45,I34,I23) -> 4936552.6 | J52: =SUM(J45,J34,J23) -> 5688512.1 | K52: =SUM(K45,K34,K23) -> 6423926.2 | L52: =SUM(L45,L34,L23) -> 7120801.9 | M52: =SUM(M45,M34,M23) -> 7881281.7
A56: 2. | B56: INCOME STATEMENT | D56: 2021 | E56: 2022 | F56: 2023 | G56: 2024 | H56: 2025 | I56: 2026 | J56: 2027 | K56: 2028 | L56: 2029 | M56: 2030
B58: Net Revenue | D58: 2667131 | E58: 3563231 | F58: 3732940 | G58: 3801378.5 | H58: =H52 -> 4260941.6 | I58: =I52 -> 4936552.6 | J58: =J52 -> 5688512.1 | K58: =K52 -> 6423926.2 | L58: =L52 -> 7120801.9 | M58: =M52 -> 7881281.7
B59: Cost of goods sold | D59: -1249944 | E59: -1508841 | F59: -1518816 | G59: -1449986 | H59: =H60-H58 -> -1619157.8 | I59: =I60-I58 -> -1858612 | J59: =J60-J58 -> -2127503.5 | K59: =K60-K58 -> -2386488.6 | L59: =L60-L58 -> -2627575.9 | M59: =M60-M58 -> -2888489.7
B60: Gross Profit | D60: =SUM(D58:D59) -> 1417187 | E60: =SUM(E58:E59) -> 2054390 | F60: =SUM(F58:F59) -> 2214124 | G60: =SUM(G58:G59) -> 2351392.5 | H60: =H58*H82 -> 2641783.8 | I60: =I58*I82 -> 3077940.5 | J60: =J58*J82 -> 3561008.6 | K60: =K58*K82 -> 4037437.6 | L60: =L58*L82 -> 4493226 | M60: =M58*M82 -> 4992791.9
B61: Selling, general & administrative | D61: -1173627 | E61: -1630131 | F61: -1604432 | G61: -1512498 | H61: =H58*-H83 -> -1837750.1 | I61: =I58*-I83 -> -2105446.6 | J61: =J58*-J83 -> -2411937.1 | K61: =K58*-K83 -> -2707693.9 | L61: =L58*-L83 -> -2983626 | M61: =M58*-M83 -> -3282564.8
B62: Equity in Earnings (Losses) of Associates | D62: -544 | E62: -14342 | F62: -6892 | G62: -11770 | H62: =AVERAGE(D62:G62) -> -8387 | I62: =AVERAGE(E62:H62) -> -10347.75 | J62: =AVERAGE(F62:I62) -> -9349.1875 | K62: =AVERAGE(G62:J62) -> -9963.4844 | L62: =AVERAGE(H62:K62) -> -9511.8555 | M62: =AVERAGE(I62:L62) -> -9793.0693
B63: Other Operating Income (Expenses) | D63: 54431 | E63: -31815 | F63: -77898 | G63: -7026 | H63: =AVERAGE(D63:G63) -> -15577 | I63: =AVERAGE(E63:H63) -> -33079 | J63: =AVERAGE(F63:I63) -> -33395 | K63: =AVERAGE(G63:J63) -> -22269.25 | L63: =AVERAGE(H63:K63) -> -26080.062 | M63: =AVERAGE(I63:L63) -> -28705.828
...

Sheet WACC
B2: Weighted Average Cost of Capital (WACC)
B3: R$ Thousands ('000) Except per Share Data
A5: 1. | B5: WACC BUILD UP
B7: Cost of Debt (pre-tax) | C7: ='Financial Statement Model'!H227 -> 0.1845
B8: Tax Rate | C8: ='Financial Statement Model'!$I$77 -> 0.15 | G8: WACC Sensitivity
B9: Cost of Debt (Kd) | C9: =C7*(1-C8) -> 0.156825
J10: Beta:
G11: =C22 -> 0.21386748 | H11: =I11-0.2 -> 1.7483559 | I11: =J11-0.2 -> 1.9483559 | J11: 2.1483559 | K11: =J11+0.2 -> 2.3483559 | L11: =K11+0.2 -> 2.5483559
B12: Risk Free Rate | C12: 0.1375 | G12: =G13-0.5% -> 0.0781 | H12: 0.1961707 | I12: 0.20141358 | J12: 0.20665647 | K12: 0.21189936 | L12: 0.21714225
B13: Leveraged Beta | C13: =Beta!K8 -> 2.1483559 | G13: =G14-0.5% -> 0.0831 | H13: 0.19910489 | I13: 0.20468343 | J13: 0.21026198 | K13: 0.21584052 | L13: 0.22141906
B14: Equity Risk Premium | C14: 0.0881 | F14: ERP: | G14: 0.0881 | H14: 0.20203909 | I14: 0.20795329 | J14: 0.21386748 | K14: 0.21978167 | L14: 0.22569586
B15: Cost of Equity (Ke) | C15: =C12+C13*C14 -> 0.32677016 | G15: =G14+0.5% -> 0.0931 | H15: 0.20497329 | I15: 0.21122314 | J15: 0.21747298 | K15: 0.22372283 | L15: 0.22997267
G16: =G15+0.5% -> 0.0981 | H16: 0.20790749 | I16: 0.21449299 | J16: 0.22107848 | K16: 0.22766398 | L16: 0.23424948
B18: Kd | C18: =C9 -> 0.156825
B19: % of Capital Structure | C19: ='Financial Statement Model'!H141 -> 0.66434773
B20: Ke | C20: =C15 -> 0.32677016
B21: % of Capital Structure | C21: ='Financial Statement Model'!H144 -> 0.33565227
B22: WACC | C22: =C18*C19+C20*C21 -> 0.21386748

Sheet Beta
B2: Market Beta
B3: R$ Thousands ('000) Except per Share Data
A5: 1. | B5: BETA BUILD UP
C7: ANIM3 | G7: IBOV
B8: {=_xlfn.STOCKHISTORY(C7,"01/01/2020","01/12/2025",2)} -> Data | C8: Fechamento | D8: Var. | F8: {=_xlfn.STOCKHISTORY(G7,"01/01/2020","10/12/2025",2)} -> Data | G8: Fechamento | H8: Var. | J8: Leveraged Beta | K8: =K9/K10 -> 2.1483559
B9: 43831 | C9: 12.096 | D9: - | F9: 43831 | G9: 113760.57 | H9: - | J9: Covariance (ANIM3;IBOV) | K9: =_xlfn.COVARIANCE.S(D10:D80,H10:H80) -> 0.0093222821
B10: 43862 | C10: 11.7978 | D10: =C10/C9-1 -> -0.024652778 | F10: 43862 | G10: 104171.57 | H10: =G10/G9-1 -> -0.084291069 | J10: Variance (IBOV) | K10: =_xlfn.VAR.S(H10:H80) -> 0.0043392633
B11: 43891 | C11: 6.2496 | D11: =C11/C10-1 -> -0.47027412 | F11: 43891 | G11: 73019.76 | H11: =G11/G10-1 -> -0.2990433
B12: 43922 | C12: 7.4654 | D12: =C12/C11-1 -> 0.19454045 | F12: 43922 | G12: 80505.89 | H12: =G12/G11-1 -> 0.10252197
B13: 43952 | C13: 7.1868 | D13: =C13/C12-1 -> -0.037318831 | F13: 43952 | G13: 87402.59 | H13: =G13/G12-1 -> 0.085667024
B14: 43983 | C14: 8.052 | D14: =C14/C13-1 -> 0.12038738 | F14: 43983 | G14: 95055.82 | H14: =G14/G13-1 -> 0.087562966
B15: 44013 | C15: 9.4186 | D15: =C15/C14-1 -> 0.16972181 | F15: 44013 | G15: 102912.24 | H15: =G15/G14-1 -> 0.082650594
B16: 44044 | C16: 9.8118 | D16: =C16/C15-1 -> 0.041747181 | F16: 44044 | G16: 99369.15 | H16: =G16/G15-1 -> -0.034428266
B17: 44075 | C17: 8.5501 | D17: =C17/C16-1 -> -0.12859007 | F17: 44075 | G17: 94603.38 | H17: =G17/G16-1 -> -0.047960257
B18: 44105 | C18: 9.1466 | D18: =C18/C17-1 -> 0.069765266 | F18: 44105 | G18: 93952.4 | H18: =G18/G17-1 -> -0.0068811495
B19: 44136 | C19: 11.765 | D19: =C19/C18-1 -> 0.28627031 | F19: 44136 | G19: 108893.32 | H19: =G19/G18-1 -> 0.15902649
B20: 44166 | C20: 11.7978 | D20: =C20/C19-1 -> 0.0027879303 | F20: 44166 | G20: 119237.56 | H20: =G20/G19-1 -> 0.094994257
B21: 44197 | C21: 10.9883 | D21: =C21/C20-1 -> -0.068614487 | F21: 44197 | G21: 115067.55 | H21: =G21/G20-1 -> -0.034972286
B22: 44228 | C22: 9.1237 | D22: =C22/C21-1 -> -0.16968958 | F22: 44228 | G22: 110035.17 | H22: =G22/G21-1 -> -0.043734137
... B80: 45992 | C80: 3.31 | D80: =C80/C79-1 -> -0.13577023 | F80: 45992 | G80: 161125.37 | H80: =G80/G79-1 -> 0.012907604

Sheet DCF
B2: Discounted Cash Flow (DFC)
B3: R$ Thousands ('000) Except per Share Data
B5: Valuation Date | C5: 46053
B6: WACC | C6: =WACC!C22 -> 0.21386748
B7: 2025 Stub Adjustment | C7: 0
B8: 2026 Stub Adjustment | C8: =YEARFRAC(D37,F37) -> 0.91666667
B9: Terminal Value Approach: | C9: EBITDA Exit Multiple
B10: Current Share Price | C10: ='Higher Education Peers Data'!C10 -> 5.23
A14: 1. | B14: UNLEVERED FREE CASH FLOWS | D14: 2024 | E14: 2025 | F14: 2026 | G14: 2027 | H14: 2028 | I14: 2029 | J14: 2030
B16: Net Revenue | D16: ='Financial Statement Model'!G58 -> 3801378.5 | E16: ='Financial Statement Model'!H58 -> 4260941.6 | F16: ='Financial Statement Model'!I58 -> 4936552.6 | G16: ='Financial Statement Model'!J58 -> 5688512.1 | H16: ='Financial Statement Model'!K58 -> 6423926.2 | I16: ='Financial Statement Model'!L58 -> 7120801.9 | J16: ='Financial Statement Model'!M58 -> 7881281.7
B17: % Growth Rate | D17: - | E17: =E16/D16-1 -> 0.12089381 | F17: =F16/E16-1 -> 0.15855907 | G17: =G16/F16-1 -> 0.15232483 | H17: =H16/G16-1 -> 0.12928057 | I17: =I16/H16-1 -> 0.10848128 | J17: =J16/I16-1 -> 0.10679692
B19: EBITDA | D19: ='Financial Statement Model'!G75 -> 1301134.5 | E19: ='Financial Statement Model'!H75 -> 1251741.8 | F19: ='Financial Statement Model'!I75 -> 1382169.4 | G19: ='Financial Statement Model'!J75 -> 1545691.7 | H19: ='Financial Statement Model'!K75 -> 1727421.1 | I19: ='Financial Statement Model'!L75 -> 1898383.6 | J19: ='Financial Statement Model'!M75 -> 2094281.3
B20: % Growth Rate | D20: - | E20: =E19/D19-1 -> -0.037961231 | F20: =F19/E19-1 -> 0.10419684 | G20: =G19/F19-1 -> 0.11830845 | H20: =H19/G19-1 -> 0.11757155 | I20: =I19/H19-1 -> 0.098969833 | J20: =J19/I19-1 -> 0.10319184
B22: EBIT | D22: ='Financial Statement Model'!G64 -> 820098.5 | E22: ='Financial Statement Model'!H64 -> 780069.74 | F22: ='Financial Statement Model'!I64 -> 929067.21 | G22: ='Financial Statement Model'!J64 -> 1106327.3 | H22: ='Financial Statement Model'!K64 -> 1297511 | I22: ='Financial Statement Model'!L64 -> 1474008.2 | J22: ='Financial Statement Model'!M64 -> 1671728.2
B23: % Growth Rate | D23: - | E23: =E22/D22-1 -> -0.048809704 | F23: =F22/E22-1 -> 0.19100533 | G23: =G22/F22-1 -> 0.19079363 | H23: =H22/G22-1 -> 0.17280935 | I23: =I22/H22-1 -> 0.13602747 | J23: =J22/I22-1 -> 0.1341377
B25: Tax Rate | E25: ='Financial Statement Model'!H77 -> 0 | F25: ='Financial Statement Model'!I77 -> 0.15 | G25: ='Financial Statement Model'!J77 -> 0.15 | H25: ='Financial Statement Model'!K77 -> 0.15 | I25: ='Financial Statement Model'!L77 -> 0.15 | J25: ='Financial Statement Model'!M77 -> 0.15
B26: NOPAT | E26: =E22*(1-E25) -> 780069.74 | F26: =F22*(1-F25) -> 789707.13 | G26: =G22*(1-G25) -> 940378.22 | H26: =H22*(1-H25) -> 1102884.4 | I26: =I22*(1-I25) -> 1252906.9 | J26: =J22*(1-J25) -> 1420969
B28: Net Working Capital | D28: =SUM('Financial Statement Model'!G90:G91)-SUM('Financial Statement Model'!G98:G100) -> 238749.85 | E28: =SUM('Financial Statement Model'!H90:H91)-SUM('Financial Statement Model'!H98:H100) -> 329806.39 | F28: =SUM('Financial Statement Model'!I90:I91)-SUM('Financial Statement Model'!I98:I100) -> 455682.86 | G28: =SUM('Financial Statement Model'!J90:J91)-SUM('Financial Statement Model'!J98:J100) -> 592661.68 | H28: =SUM('Financial Statement Model'!K90:K91)-SUM('Financial Statement Model'!K98:K100) -> 726752.3 | I28: =SUM('Financial Statement Model'!L90:L91)-SUM('Financial Statement Model'!L98:L100) -> 854480.75 | J28: =SUM('Financial Statement Model'!M90:M91)-SUM('Financial Statement Model'!M98:M100) -> 992119.11
B30: Depreciation & Amortization | E30: ='Financial Statement Model'!H74 -> 471672.1 | F30: ='Financial Statement Model'!I74 -> 453102.16 | G30: ='Financial Statement Model'!J74 -> 439364.38 | H30: ='Financial Statement Model'!K74 -> 429910.05 | I30: ='Financial Statement Model'!L74 -> 424375.49 | J30: ='Financial Statement Model'!M74 -> 422553.13
B31: CAPEX | E31: ='Financial Statement Model'!H126 -> -256845.56 | F31: ='Financial Statement Model'!I126 -> -288376.18 | G31: ='Financial Statement Model'!J126 -> -319764.05 | H31: ='Financial Statement Model'!K126 -> -351981.04 | I31: ='Financial Statement Model'!L126 -> -385938.19 | J31: ='Financial Statement Model'!M126 -> -422553.13
B32: Changes in Net Working Capital | E32: =D28-E28 -> -91056.538 | F32: =E28-F28 -> -125876.47 | G32: =F28-G28 -> -136978.82 | H32: =G28-H28 -> -134090.61 | I32: =H28-I28 -> -127728.46 | J32: =I28-J28 -> -137638.35
B33: Unlevered Free Cash Flows (UFCF) | E33: =E26+E30+E31+E32 -> 903839.73 | F33: =F26+F30+F31+F32 -> 828556.65 | G33: =G26+G30+G31+G32 -> 922999.72 | H33: =H26+H30+H31+H32 -> 1046722.8 | I33: =I26+I30+I31+I32 -> 1163615.8 | J33: =J26+J30+J31+J32 -> 1283330.6
E36: Year 1 (Stub) | F36: Year 2 (Stub) | G36: Year 3 | H36: Year 4 | I36: Year 5 | J36: Year 6
B37: Date for Discounting Cash Flows | D37: =C5 -> 46053 | E37: 46022 | F37: 46387 | G37: 46752 | H37: 47118 | I37: 47483 | J37: 47848
B38: Unlevered Free Cash Flows (Stub Adjusted) | E38: =C7*E33 -> 0 | F38: =C8*F33 -> 759510.26 | G38: =G33 -> 922999.72 | H38: =H33 -> 1046722.8 | I38: =I33 -> 1163615.8 | J38: =J33 -> 1283330.6
B39: Present Value of Adjusted Unlevered Free Cash Flows | E39: =E38/(1+$C$6)^((E37-$C$5)/365) -> 0 | F39: =F38/(1+$C$6)^((F37-$C$5)/365) -> 636079.15 | G39: =G38/(1+$C$6)^((G37-$C$5)/365) -> 636806.97 | H39: =H38/(1+$C$6)^((H37-$C$5)/365) -> 594615.23 | I39: =I38/(1+$C$6)^((I37-$C$5)/365) -> 544556.17 | J39: =J38/(1+$C$6)^((J37-$C$5)/365) -> 494766.59
A44: 2. | B44: TERMINAL VALUE
B46: Perpetuity Growth Approach | F46: EBITDA Exit Multiple Approach
B47: Long Term Growth Rate (g) | C47: 0.05 | F47: Terminal Year EBITDA | J47: =J19 -> 2094281.3
B48: 2030 UFCF x (1+g) | C48: =J38*(1+C47) -> 1347497.2 | F48: EBITDA Exit Multiple | J48: 4.5
B49: Terminal Value in 2030 | C49: =C48/(C6-C47) -> 8223090.8 | F49: Terminal Value in 2030 | J49: =J47*J48 -> 9424266
B50: Present Value of Terminal Value | C50: =C49/(1+C6)^((J37-D37)/365) -> 3170274.7 | F50: Present Value of Terminal Value | J50: =J49/(1+C6)^((J37-D37)/365) -> 3633367.6
B51: Present Value of UFCF | C51: =SUM(E39:J39) -> 2906824.1 | F51: Present Value of UFCF | J51: =SUM(E39:J39) -> 2906824.1
B52: Total Enterprise Value (EV) | C52: =SUM(C50:C51) -> 6077098.8 | F52: Total Enterprise Value (EV) | J52: =SUM(J50:J51) -> 6540191.8
B54: Terminal Value as % of EV | C54: =C50/$C$52 -> 0.52167569 | F54: Terminal Value as % of EV | J54: =J50/$J$52 -> 0.55554451
B55: UFCF as % of EV | C55: =C51/$C$52 -> 0.47832431 | F55: UFCF as % of EV | J55: =J51/$J$52 -> 0.44445549
B56: Implied TV Exit EBITDA Multiple | C56: =C49/I19 -> 4.3316275 | F56: Implied Terminal Growth Rate | J56: =(C6-J38/J49)/(1+J38/J49) -> 0.068382608
A60: 3. | B60: DCF RESULTS
B62: Enterprise Value | C62: =IF($C$9="Perpetuity Growth",C52,J52) -> 6540191.8 | E62: Equity Value per Share Sensitivity | L62: Enterprise Value Sensitivity
B64: Net Debt | C64: =-'Higher Education Peers Data'!C47 -> -4387109 | H64: =C9&":" -> EBITDA Exit Multiple: | O64: =C9&":" -> EBITDA Exit Multiple:
...

Sheet Higher Education Peers Data
B2: Higher Education Peers Data
B3: R$ Thousands ('000) Except per Share Data
A5: 1. | B5: GENERAL INPUTS
B7: Ticker | C7: ANIM3 | E7: COGN3 | G7: YDUQ3 | I7: SEER3 | K7: CSED3 | M7: AFYA | O7: VTRU3
B8: Stock Data | C8: #VALUE! | E8: #VALUE! | G8: #VALUE! | I8: #VALUE! | K8: #VALUE! | M8: #VALUE! | O8: #VALUE!
B9: Company Name | C9: Ânima | E9: Cogna | G9: Yduqs | I9: Ser Educacional | K9: Cruzeiro do Sul | M9: Afya | O9: Vitru
B10: Last Closing Share Price (31/01/2026) | C10: 5.23 | E10: 4.59 | G10: 14.68 | I10: 12.5 | K10: 7.2 | M10: 79.1104 | O10: 16.55
B12: Source | C12: 3T25 ITR/DFP | E12: 3T25 ITR/DFP | G12: 3T25 ITR/DFP | I12: 3T25 ITR/DFP | K12: 3T25 ITR/DFP | M12: Afya Corporate Structure | O12: CVM
B13: Basic Share Count (Thousands) | C13: 403868.8 | E13: 1876606.2 | G13: =274089+10621 -> 284710 | I13: 129828.48 | K13: 364542.55 | M13: 93722.831 | O13: 134692.33
A17: 2. | B17: BALANCE SHEET DATA
B19: Source | C19: 3T25 ITR/DFP | E19: 3T25 ITR/DFP | G19: 3T25 ITR/DFP | I19: 3T25 ITR/DFP | K19: 3T25 ITR/DFP | M19: 3Q25 Spreadsheet | O19: CVM
B21: Cash | C21: 112989 | E21: 20121 | G21: 625153 | I21: 280612 | K21: 839576 | M21: 996826 | O21: 34271
B22: Short-Term Investments (marketable securities) | C22: 1563474 | E22: 1256921 | G22: 430817 | I22: 18347 | K22: - | M22: - | O22: 751109
B23: Long-Term Investments (marketable securities) | C23: - | E23: 42616 | G23: - | I23: 61288 | K23: - | M23: - | O23: -
B24: Cash & Cash Equivalents | C24: =SUM(C21:C23) -> 1676463 | E24: =SUM(E21:E23) -> 1319658 | G24: =SUM(G21:G23) -> 1055970 | I24: =SUM(I21:I23) -> 360247 | K24: =SUM(K21:K23) -> 839576 | M24: =SUM(M21:M23) -> 996826 | O24: =SUM(O21:O23) -> 785380
B26: Total Short-Term Debt (including leases) | C26: 532910 | E26: =60148+194133+213194 -> 467475 | G26: 1283997 | I26: 357867 | K26: =185815+143387 -> 329202 | M26: 969389 | O26: 114329
B27: Total Long-Term Debt (including leases) | C27: 4978581 | E27: =597148+2779346+2689298 -> 6065792 | G27: 4028603 | I27: 1182582 | K27: =1078289+1048154 -> 2126443 | M27: 2005183 | O27: 2335341
B28: Total Debt | C28: =SUM(C26:C27) -> 5511491 | E28: =SUM(E26:E27) -> 6533267 | G28: =SUM(G26:G27) -> 5312600 | I28: =SUM(I26:I27) -> 1540449 | K28: =SUM(K26:K27) -> 2455645 | M28: =SUM(M26:M27) -> 2974572 | O28: =SUM(O26:O27) -> 2449670
B30: Non-Controlling Interest | C30: 552081 | E30: 1123268 | G30: 24165 | I30: - | K30: - | M30: 40519 | O30: -
B31: Preferred Stock | C31: - | E31: - | G31: - | I31: - | K31: - | M31: - | O31: -
B33: Total Shareholders' Equity | C33: 2906509 | E33: 13885799 | G33: 3158533 | I33: 1328928 | K33: 1656113 | M33: 4786592 | O33: 2834844
A37: 3. | B37: MARKET VALUATION DATA
B39: Price Per Share | C39: =C10 -> 5.23 | E39: =E10 -> 4.59 | G39: =G10 -> 14.68 | I39: =I10 -> 12.5 | K39: =K10 -> 7.2 | M39: =M10 -> 79.1104 | O39: =O10 -> 16.55
B40: Basic Share Count (Thousands) | C40: =C13 -> 403868.8 | E40: =E13 -> 1876606.2 | G40: =G13 -> 284710 | I40: =I13 -> 129828.48 | K40: =K13 -> 364542.55 | M40: =M13 -> 93722.831 | O40: =O13 -> 134692.33
B41: Market Value of Equity | C41: =C39*C40 -> 2112233.9 | E41: =E39*E40 -> 8613622.5 | G41: =G39*G40 -> 4179542.8 | I41: =I39*I40 -> 1622856 | K41: =K39*K40 -> 2624706.4 | M41: =M39*M40 -> 7414450.6 | O41: =O39*O40 -> 2229158
B43: Total Debt | C43: =C28 -> 5511491 | E43: =E28 -> 6533267 | G43: =G28 -> 5312600 | I43: =I28 -> 1540449 | K43: =K28 -> 2455645 | M43: =M28 -> 2974572 | O43: =O28 -> 2449670
B44: Non-Controlling Interest | C44: =C30 -> 552081 | E44: =E30 -> 1123268 | G44: =G30 -> 24165 | I44: =I30 -> - | K44: =K30 -> - | M44: =M30 -> 40519 | O44: =O30 -> -
B45: Preferred Stock | C45: =C31 -> - | E45: =E31 -> - | G45: =G31 -> - | I45: =I31 -> - | K45: =K31 -> - | M45: =M31 -> - | O45: =O31 -> -
B46: Cash & Cash Equivalents | C46: =C24 -> 1676463 | E46: =E24 -> 1319658 | G46: =G24 -> 1055970 | I46: =I24 -> 360247 | K46: =K24 -> 839576 | M46: =M24 -> 996826 | O46: =O24 -> 785380
B47: Net Debt | C47: =SUM(C43:C45)-C46 -> 4387109 | E47: =SUM(E43:E45)-E46 -> 6336877 | G47: =SUM(G43:G45)-G46 -> 4280795 | I47: =SUM(I43:I45)-I46 -> 1180202 | K47: =SUM(K43:K45)-K46 -> 1616069 | M47: =SUM(M43:M45)-M46 -> 2018265 | O47: =SUM(O43:O45)-O46 -> 1664290
B49: Enterprise Value | C49: =C41+C47 -> 6499342.9 | E49: =E41+E47 -> 14950500 | G49: =G41+G47 -> 8460337.8 | I49: =I41+I47 -> 2803058 | K49: =K41+K47 -> 4240775.4 | M49: =M41+M47 -> 9432715.6 | O49: =O41+O47 -> 3893448
A53: 4. | B53: INCOME STATEMENT DATA
B55: LATEST FULL YEAR END
B56: Source | C56: 4T24 ITR/DFP | E56: 4T24 ITR/DFP | G56: 4T24 ITR/DFP | I56: 4T24 ITR/DFP | K56: 4T24 ITR/DFP | M56: 2024 20-F | O56: 4T24 ITR/DFP
B58: Net Revenue | C58: 3801378.5 | E58: 6422449 | G58: 5351785 | I58: 1981354 | K58: 2568352 | M58: 3304329 | O58: 2141809
B59: Cost of goods sold | C59: -1449986 | E59: -2138015 | G59: -2086676 | I59: -887127 | K59: -1317230 | M59: -1215603 | O59: -746646
B60: Gross Profit | C60: =SUM(C58:C59) -> 2351392.5 | E60: =SUM(E58:E59) -> 4284434 | G60: =SUM(G58:G59) -> 3265109 | I60: =SUM(I58:I59) -> 1094227 | K60: =SUM(K58:K59) -> 1251122 | M60: =SUM(M58:M59) -> 2088726 | O60: =SUM(O58:O59) -> 1395163
B61: Operating Expenses | C61: -1531294 | E61: -2934166 | G61: -2347609 | I61: -855298 | K61: -781207 | M61: -1064900 | O61: -947433
B62: Operating profit (EBIT) | C62: =SUM(C60:C61) -> 820098.5 | E62: =SUM(E60:E61) -> 1350268 | G62: =SUM(G60:G61) -> 917500 | I62: =SUM(I60:I61) -> 238929 | K62: =SUM(K60:K61) -> 469915 | M62: =SUM(M60:M61) -> 1023826 | O62: =SUM(O60:O61) -> 447730
B63: Interest income | C63: 169996.96 | E63: 559564 | G63: 299061 | I63: 92181 | K63: 75896 | M63: 111283 | O63: 57589
...

Sheet Trading Comps
B2: Trading Comparables Analysis (Trading Comps)
B3: R$ Thousands ('000) Except per Share Data
A5: 1. | B5: COMPARABLES DATA
B8: *Capital IQ estimates for peers in 2026 | I8: Net Revenue | L8: EBITDA | O8: Net Income | R8: EV / Revenue | U8: EV / EBITDA | X8: Price / Earnings
B9: Ticker | C9: Company | E9: Enterprise Value | F9: Market Cap. | G9: Price | I9: LTM | J9: 2026P* | L9: LTM | M9: 2026P* | O9: LTM | P9: 2026P* | R9: LTM | S9: 2026P | U9: LTM | V9: 2026P | X9: LTM | Y9: 2026P
B10: ='Higher Education Peers Data'!C7 -> ANIM3 | C10: ='Higher Education Peers Data'!C9 -> Ânima | E10: ='Higher Education Peers Data'!C49 -> 6499342.9 | F10: ='Higher Education Peers Data'!C41 -> 2112233.9 | G10: ='Higher Education Peers Data'!C10 -> 5.23 | I10: ='Higher Education Peers Data'!C79 -> 3946759.5 | J10: ='Financial Statement Model'!I58 -> 4936552.6 | L10: ='Higher Education Peers Data'!C91 -> 1415835.5 | M10: ='Financial Statement Model'!I75 -> 1382169.4 | O10: ='Higher Education Peers Data'!C88 -> 294546.82 | P10: ='Financial Statement Model'!I69 -> 241856.8 | R10: =IFERROR($E10/I10,"-") -> 1.6467542 | S10: =IFERROR($E10/J10,"-") -> 1.3165752 | U10: =IFERROR($E10/L10,"-") -> 4.5904647 | V10: =IFERROR($E10/M10,"-") -> 4.7022767 | X10: =IFERROR($E10/O10,"-") -> 22.065568 | Y10: =IFERROR($E10/P10,"-") -> 26.87269
B11: ='Higher Education Peers Data'!E7 -> COGN3 | C11: ='Higher Education Peers Data'!E9 -> Cogna | E11: ='Higher Education Peers Data'!E49 -> 14950500 | F11: ='Higher Education Peers Data'!E41 -> 8613622.5 | G11: ='Higher Education Peers Data'!E10 -> 4.59 | I11: ='Higher Education Peers Data'!E79 -> 6976160 | J11: 7268789.8 | L11: ='Higher Education Peers Data'!E91 -> 2248748 | M11: 2418664.6 | O11: ='Higher Education Peers Data'!E88 -> 1443896 | P11: 902376.45 | R11: =IFERROR($E11/I11,"-") -> 2.1430844 | S11: =IFERROR($E11/J11,"-") -> 2.0568072 | U11: =IFERROR($E11/L11,"-") -> 6.6483659 | V11: =IFERROR($E11/M11,"-") -> 6.1813032 | X11: =IFERROR($E11/O11,"-") -> 10.354277 | Y11: =IFERROR($E11/P11,"-") -> 16.567919
B12: ='Higher Education Peers Data'!G7 -> YDUQ3 | C12: ='Higher Education Peers Data'!G9 -> Yduqs | E12: ='Higher Education Peers Data'!G49 -> 8460337.8 | F12: ='Higher Education Peers Data'!G41 -> 4179542.8 | G12: ='Higher Education Peers Data'!G10 -> 14.68 | I12: ='Higher Education Peers Data'!G79 -> 5483298 | J12: 5572441.9 | L12: ='Higher Education Peers Data'!G91 -> 1702550 | M12: 1840664.5 | O12: ='Higher Education Peers Data'!G88 -> 243466 | P12: 413812.7 | R12: =IFERROR($E12/I12,"-") -> 1.5429287 | S12: =IFERROR($E12/J12,"-") -> 1.518246 | U12: =IFERROR($E12/L12,"-") -> 4.9692155 | V12: =IFERROR($E12/M12,"-") -> 4.5963498 | X12: =IFERROR($E12/O12,"-") -> 34.749566 | Y12: =IFERROR($E12/P12,"-") -> 20.444848
B13: ='Higher Education Peers Data'!I7 -> SEER3 | C13: ='Higher Education Peers Data'!I9 -> Ser Educacional | E13: ='Higher Education Peers Data'!I49 -> 2803058 | F13: ='Higher Education Peers Data'!I41 -> 1622856 | G13: ='Higher Education Peers Data'!I10 -> 12.5 | I13: ='Higher Education Peers Data'!I79 -> 2167439 | J13: 2208985.7 | L13: ='Higher Education Peers Data'!I91 -> 563163 | M13: 535644.44 | O13: ='Higher Education Peers Data'!I88 -> 109670 | P13: 140000 | R13: =IFERROR($E13/I13,"-") -> 1.2932581 | S13: =IFERROR($E13/J13,"-") -> 1.2689345 | U13: =IFERROR($E13/L13,"-") -> 4.9773477 | V13: =IFERROR($E13/M13,"-") -> 5.2330573 | X13: =IFERROR($E13/O13,"-") -> 25.559023 | Y13: =IFERROR($E13/P13,"-") -> 20.021843
B14: ='Higher Education Peers Data'!K7 -> CSED3 | C14: ='Higher Education Peers Data'!K9 -> Cruzeiro do Sul | E14: ='Higher Education Peers Data'!K49 -> 4240775.4 | F14: ='Higher Education Peers Data'!K41 -> 2624706.4 | G14: ='Higher Education Peers Data'!K10 -> 7.2 | I14: ='Higher Education Peers Data'!K79 -> 2749814 | J14: 2795739 | L14: ='Higher Education Peers Data'!K91 -> 733714 | M14: 865291.22 | O14: ='Higher Education Peers Data'!K88 -> 252531 | P14: 228500 | R14: =IFERROR($E14/I14,"-") -> 1.5422044 | S14: =IFERROR($E14/J14,"-") -> 1.516871 | U14: =IFERROR($E14/L14,"-") -> 5.7798752 | V14: =IFERROR($E14/M14,"-") -> 4.9009805 | X14: =IFERROR($E14/O14,"-") -> 16.793088 | Y14: =IFERROR($E14/P14,"-") -> 18.559192
B15: ='Higher Education Peers Data'!M7 -> AFYA | C15: ='Higher Education Peers Data'!M9 -> Afya | E15: ='Higher Education Peers Data'!M49 -> 9432715.6 | F15: ='Higher Education Peers Data'!M41 -> 7414450.6 | G15: ='Higher Education Peers Data'!M10 -> 79.1104 | I15: ='Higher Education Peers Data'!M79 -> 3633280 | J15: 4000538.8 | L15: ='Higher Education Peers Data'!M91 -> 1558553 | M15: 1678265 | O15: ='Higher Education Peers Data'!M88 -> 747277 | P15: 883174.07 | R15: =IFERROR($E15/I15,"-") -> 2.5961984 | S15: =IFERROR($E15/J15,"-") -> 2.3578613 | U15: =IFERROR($E15/L15,"-") -> 6.0522264 | V15: =IFERROR($E15/M15,"-") -> 5.6205162 | X15: =IFERROR($E15/O15,"-") -> 12.622783 | Y15: =IFERROR($E15/P15,"-") -> 10.680472
B16: ='Higher Education Peers Data'!O7 -> VTRU3 | C16: ='Higher Education Peers Data'!O9 -> Vitru | E16: ='Higher Education Peers Data'!O49 -> 3893448 | F16: ='Higher Education Peers Data'!O41 -> 2229158 | G16: ='Higher Education Peers Data'!O10 -> 16.55 | I16: ='Higher Education Peers Data'!O79 -> 2231001 | J16: 2274500 | L16: ='Higher Education Peers Data'!O91 -> 715170 | M16: 826000 | O16: ='Higher Education Peers Data'!O88 -> 469944 | P16: 441000 | R16: =IFERROR($E16/I16,"-") -> 1.7451575 | S16: =IFERROR($E16/J16,"-") -> 1.7117819 | U16: =IFERROR($E16/L16,"-") -> 5.4440875 | V16: =IFERROR($E16/M16,"-") -> 4.7136175 | X16: =IFERROR($E16/O16,"-") -> 8.2849191 | Y16: =IFERROR($E16/P16,"-") -> 8.8286803
B18: Max | R18: =IFERROR(MAX(R10:R16),"-") -> 2.5961984 | S18: =IFERROR(MAX(S10:S16),"-") -> 2.3578613 | U18: =IFERROR(MAX(U10:U16),"-") -> 6.6483659 | V18: =IFERROR(MAX(V10:V16),"-") -> 6.1813032 | X18: =IFERROR(MAX(X10:X16),"-") -> 34.749566 | Y18: =IFERROR(MAX(Y10:Y16),"-") -> 26.87269
B19: 75th Percentile | R19: =IFERROR(_xlfn.QUARTILE.INC(R10:R16,3),"-") -> 1.9441209 | S19: =IFERROR(_xlfn.QUARTILE.INC(S10:S16,3),"-") -> 1.8842946 | U19: =IFERROR(_xlfn.QUARTILE.INC(U10:U16,3),"-") -> 5.9160508 | V19: =IFERROR(_xlfn.QUARTILE.INC(V10:V16,3),"-") -> 5.4267867 | X19: =IFERROR(_xlfn.QUARTILE.INC(X10:X16,3),"-") -> 23.812295 | Y19: =IFERROR(_xlfn.QUARTILE.INC(Y10:Y16,3),"-") -> 20.233346
B20: Median | R20: =IFERROR(MEDIAN(R10:R16),"-") -> 1.6467542 | S20: =IFERROR(MEDIAN(S10:S16),"-") -> 1.518246 | U20: =IFERROR(MEDIAN(U10:U16),"-") -> 5.4440875 | V20: =IFERROR(MEDIAN(V10:V16),"-") -> 4.9009805 | X20: =IFERROR(MEDIAN(X10:X16),"-") -> 16.793088 | Y20: =IFERROR(MEDIAN(Y10:Y16),"-") -> 18.559192
B21: 25th Percentile | R21: =IFERROR(_xlfn.QUARTILE.INC(R10:R16,1),"-") -> 1.5425666 | S21: =IFERROR(_xlfn.QUARTILE.INC(S10:S16,1),"-") -> 1.4167231 | U21: =IFERROR(_xlfn.QUARTILE.INC(U10:U16,1),"-") -> 4.9732816 | V21: =IFERROR(_xlfn.QUARTILE.INC(V10:V16,1),"-") -> 4.7079471 | X21: =IFERROR(_xlfn.QUARTILE.INC(X10:X16,1),"-") -> 11.48853 | Y21: =IFERROR(_xlfn.QUARTILE.INC(Y10:Y16,1),"-") -> 13.624195
B22: Min | R22: =IFERROR(MIN(R10:R16),"-") -> 1.2932581 | S22: =IFERROR(MIN(S10:S16),"-") -> 1.2689345 | U22: =IFERROR(MIN(U10:U16),"-") -> 4.5904647 | V22: =IFERROR(MIN(V10:V16),"-") -> 4.5963498 | X22: =IFERROR(MIN(X10:X16),"-") -> 8.2849191 | Y22: =IFERROR(MIN(Y10:Y16),"-") -> 8.8286803
E25: 25th Percentile | F25: Bar | G25: 75th Percentile
C26: EV / LTM Revenue | E26: =R31 -> 6088139.3 | F26: =G26-E26 -> 1584838.4 | G26: =R29 -> 7672977.7 | R26: EV / Revenue | U26: EV / EBITDA | X26: Price / Earnings
C27: EV / LTM EBITDA | E27: =U31 -> 7041348.6 | F27: =G27-E27 -> 1334806.2 | G27: =U29 -> 8376154.8 | L27: Ânima's Data | P27: Enterprise Value | R27: LTM | S27: 2026P | U27: LTM | V27: 2026P | X27: LTM | Y27: 2026P
C28: Price / LTM Earnings | E28: =X31 -> 7771019.1 | F28: =G28-E28 -> 3629925.8 | G28: =X29 -> 11400945 | L28: Shares | M28: Net Debt | P28: Max | R28: =(R18*I$10) -> 10246571 | S28: =(S18*J$10) -> 11639706 | U28: =(U18*L$10) -> 9412992.5 | V28: =(V18*M$10) -> 8543608 | X28: =(X18*O$10)+$M$29 -> 14622483 | Y28: =(Y18*P$10)+$M$29 -> 10886452
C29: EV / 2026P Revenue | E29: =S31 -> 6993728 | F29: =G29-E29 -> 2308191.3 | G29: =S29 -> 9301919.3 | L29: ='Higher Education Peers Data'!C13 -> 403868.8 | M29: ='Higher Education Peers Data'!C47 -> 4387109 | P29: 75th Percentile | R29: =(R19*I$10) -> 7672977.7 | S29: =(S19*J$10) -> 9301919.3 | U29: =(U19*L$10) -> 8376154.8 | V29: =(V19*M$10) -> 7500738.4 | X29: =(X19*O$10)+$M$29 -> 11400945 | Y29: =(Y19*P$10)+$M$29 -> 9280681.3
C30: EV / 2026P EBITDA | E30: =V31 -> 6507180.3 | F30: =G30-E30 -> 993558.14 | G30: =V29 -> 7500738.4 | P30: Median | R30: =(R20*I$10) -> 6499342.9 | S30: =(S20*J$10) -> 7494901.3 | U30: =(U20*L$10) -> 7707932.3 | V30: =(V20*M$10) -> 6773985.1 | X30: =(X20*O$10)+$M$29 -> 9333459.8 | Y30: =(Y20*P$10)+$M$29 -> 8875775.9
C31: Price / 2026P Earnings | E31: =Y31 -> 7682213.3 | F31: =G31-E31 -> 1598468 | G31: =Y29 -> 9280681.3 | P31: 25th Percentile | R31: =(R21*I$10) -> 6088139.3 | S31: =(S21*J$10) -> 6993728 | U31: =(U21*L$10) -> 7041348.6 | V31: =(V21*M$10) -> 6507180.3 | X31: =(X21*O$10)+$M$29 -> 7771019.1 | Y31: =(Y21*P$10)+$M$29 -> 7682213.3
P32: Min | R32: =(R22*I$10) -> 5104178.7 | S32: =(S22*J$10) -> 6264161.6 | U32: =(U22*L$10) -> 6499342.9 | V32: =(V22*M$10) -> 6352933.9 | X32: =(X22*O$10)+$M$29 -> 6827405.6 | Y32: =(Y22*P$10)+$M$29 -> 6522385.4

Sheet Transaction Comps
B2: Trading Comparables Analysis (Trading Comps)
B3: R$ Thousands ('000) Except per Share Data
A5: 1. | B5: COMPARABLES DATA
B7: Date | D7: Acquirer | E7: Target | F7: State | H7: Enterprise Value | I7: Revenue | J7: EBITDA | K7: # of Students | M7: EV/Revenue | N7: EV/EBITDA | O7: EV/Student | Q7: Ânima's LTM Data
B8: 43252 | D8: Cruzeiro do Sul | E8: Unipê | F8: Paraíba | H8: 419500 | I8: 180000 | J8: - | K8: 15000 | M8: =IFERROR(H8/I8,"-") -> 2.3305556 | N8: =IFERROR(H8/J8,"-") -> - | O8: =IFERROR(H8/K8,"-") -> 27.966667 | Q8: Shares | R8: Net Debt | S8: Revenue | T8: EBITDA | U8: Students
B9: 43252 | D9: Carlyle+Vinci | E9: Uniasselvi | F9: Santa Catarina | H9: 1520000 | I9: 324000 | J9: - | K9: 100000 | M9: =IFERROR(H9/I9,"-") -> 4.691358 | N9: =IFERROR(H9/J9,"-") -> - | O9: =IFERROR(H9/K9,"-") -> 15.2 | Q9: ='Higher Education Peers Data'!C13 -> 403868.8 | R9: ='Higher Education Peers Data'!C47 -> 4387109 | S9: ='Trading Comps'!I10 -> 3946759.5 | T9: ='Trading Comps'!L10 -> 1415835.5 | U9: ='Higher Education Peers Data'!C104 -> 374987
B10: 43160 | D10: Kroton | E10: FEBAC | F10: Maranhão | H10: 13100 | I10: - | J10: - | K10: 1400 | M10: =IFERROR(H10/I10,"-") -> - | N10: =IFERROR(H10/J10,"-") -> - | O10: =IFERROR(H10/K10,"-") -> 9.3571429
B11: 43282 | D11: Ânima | E11: Cesuc | F11: Catião | H11: 26700 | I11: 22800 | J11: 5500 | K11: 2500 | M11: =IFERROR(H11/I11,"-") -> 1.1710526 | N11: =IFERROR(H11/J11,"-") -> 4.8545455 | O11: =IFERROR(H11/K11,"-") -> 10.68
B12: 43252 | D12: Ânima | E12: Jangada | F12: Santa Catarina | H12: 6700 | I12: 7200 | J12: - | K12: 700 | M12: =IFERROR(H12/I12,"-") -> 0.93055556 | N12: =IFERROR(H12/J12,"-") -> - | O12: =IFERROR(H12/K12,"-") -> 9.5714286
B13: 43313 | D13: Kroton | E13: SEPA | F13: Paraíba | H13: 6000 | I13: - | J13: - | K13: 500 | M13: =IFERROR(H13/I13,"-") -> - | N13: =IFERROR(H13/J13,"-") -> - | O13: =IFERROR(H13/K13,"-") -> 12
B14: 43435 | D14: Ânima | E14: Faced | F14: Minas Gerais | H14: 5500 | I14: 6400 | J14: - | K14: 800 | M14: =IFERROR(H14/I14,"-") -> 0.859375 | N14: =IFERROR(H14/J14,"-") -> - | O14: =IFERROR(H14/K14,"-") -> 6.875 | Q14: Enterprise Value | S14: EV/Revenue | T14: EV/EBITDA | U14: EV/Student
B15: 43466 | D15: Kroton | E15: CEMAR | F15: Pará | H15: 30000 | I15: - | J15: - | K15: 1800 | M15: =IFERROR(H15/I15,"-") -> - | N15: =IFERROR(H15/J15,"-") -> - | O15: =IFERROR(H15/K15,"-") -> 16.666667 | Q15: Max | S15: =(M44*$S$9) -> 18515662 | T15: =(N44*$T$9) -> 1.6463204e+08 | U15: =(O44*$U$9) -> 57855137
B16: 43466 | D16: Kroton | E16: CEPAR | F16: Pará | H16: 17000 | I16: - | J16: - | K16: 300 | M16: =IFERROR(H16/I16,"-") -> - | N16: =IFERROR(H16/J16,"-") -> - | O16: =IFERROR(H16/K16,"-") -> 56.666667 | Q16: 75th Percentile | S16: =(M45*$S$9) -> 9769206.7 | T16: =(N45*$T$9) -> 19814085 | U16: =(O45*$U$9) -> 14454548
B17: 43466 | D17: Kroton | E17: CESUPAR | F17: Pará | H17: 13000 | I17: - | J17: - | K17: 200 | M17: =IFERROR(H17/I17,"-") -> - | N17: =IFERROR(H17/J17,"-") -> - | O17: =IFERROR(H17/K17,"-") -> 65 | Q17: Median | S17: =(M46*$S$9) -> 8637689.1 | T17: =(N46*$T$9) -> 15113294 | U17: =(O46*$U$9) -> 6749766
B18: 43556 | D18: Ser Educacional | E18: UniNorte | F18: Amazonas | H18: 200000 | I18: 166500 | J18: 18700 | K18: 25000 | M18: =IFERROR(H18/I18,"-") -> 1.2012012 | N18: =IFERROR(H18/J18,"-") -> 10.695187 | O18: =IFERROR(H18/K18,"-") -> 8 | Q18: 25th Percentile | S18: =(M47*$S$9) -> 5381944.8 | T18: =(N47*$T$9) -> 12196403 | U18: =(O47*$U$9) -> 4145213.4
B19: 43678 | D19: Ânima | E19: UniAges | F19: Bahia | H19: 200000 | I19: 80800 | J19: 19800 | K19: 5600 | M19: =IFERROR(H19/I19,"-") -> 2.4752475 | N19: =IFERROR(H19/J19,"-") -> 10.10101 | O19: =IFERROR(H19/K19,"-") -> 35.714286 | Q19: Min | S19: =(M48*$S$9) -> 3391746.4 | T19: =(N48*$T$9) -> 6873237.8 | U19: =(O48*$U$9) -> 1166626.2
B20: 43770 | D20: Afya | E20: IPEC | F20: Pará | H20: 108000 | I20: - | J20: - | K20: 700 | M20: =IFERROR(H20/I20,"-") -> - | N20: =IFERROR(H20/J20,"-") -> - | O20: =IFERROR(H20/K20,"-") -> 154.28571
B21: 43709 | D21: Cruzeiro do Sul | E21: Braz Cubas | F21: São Paulo | H21: 150000 | I21: 96000 | J21: - | K21: 16000 | M21: =IFERROR(H21/I21,"-") -> 1.5625 | N21: =IFERROR(H21/J21,"-") -> - | O21: =IFERROR(H21/K21,"-") -> 9.375
B22: 43709 | D22: YDUQS | E22: Unitoledo | F22: São Paulo | H22: 102500 | I22: 42700 | J22: 12600 | K22: 5300 | M22: =IFERROR(H22/I22,"-") -> 2.4004684 | N22: =IFERROR(H22/J22,"-") -> 8.1349206 | O22: =IFERROR(H22/K22,"-") -> 19.339623
B23: 43739 | D23: YDUQS | E23: Adtalem | F23: - | H23: 1920000 | I23: 875000 | J23: 191000 | K23: 102000 | M23: =IFERROR(H23/I23,"-") -> 2.1942857 | N23: =IFERROR(H23/J23,"-") -> 10.052356 | O23: =IFERROR(H23/K23,"-") -> 18.823529
B24: 43770 | D24: Afya | E24: UniRedentor | F24: Rio de Janeiro | H24: 225000 | I24: - | J24: - | K24: 1500 | M24: =IFERROR(H24/I24,"-") -> - | N24: =IFERROR(H24/J24,"-") -> - | O24: =IFERROR(H24/K24,"-") -> 150 | R24: 25th Percentile | S24: Bar | T24: 75th Percentile
B25: 43770 | D25: Ânima | E25: UNISUL | F25: Santa Catarina | H25: 300000 | I25: 220000 | J25: - | K25: 19000 | M25: =IFERROR(H25/I25,"-") -> 1.3636364 | N25: =IFERROR(H25/J25,"-") -> - | O25: =IFERROR(H25/K25,"-") -> 15.789474 | Q25: EV/Revenue | R25: =S18 -> 5381944.8 | S25: =T25-R25 -> 4387261.9 | T25: =S16 -> 9769206.7
B26: 43800 | D26: Cruzeiro do Sul | E26: Positivo | F26: Paraná | H26: 500000 | I26: 350000 | J26: - | K26: 33000 | M26: =IFERROR(H26/I26,"-") -> 1.4285714 | N26: =IFERROR(H26/J26,"-") -> - | O26: =IFERROR(H26/K26,"-") -> 15.151515 | Q26: EV/EBITDA | R26: =T18 -> 12196403 | S26: =T26-R26 -> 7617682.3 | T26: =T16 -> 19814085
B27: 43800 | D27: Ânima | E27: Unicuritiba | F27: Santa Catarina | H27: 130000 | I27: 78700 | J27: 9300 | K27: 5200 | M27: =IFERROR(H27/I27,"-") -> 1.6518424 | N27: =IFERROR(H27/J27,"-") -> 13.978495 | O27: =IFERROR(H27/K27,"-") -> 25 | Q27: EV/Student | R27: =U18 -> 4145213.4 | S27: =T27-R27 -> 10309335 | T27: =U16 -> 14454548
B28: 43862 | D28: Afya | E28: UniSL | F28: Rondônia | H28: 341600 | I28: - | J28: - | K28: 5600 | M28: =IFERROR(H28/I28,"-") -> - | N28: =IFERROR(H28/J28,"-") -> - | O28: =IFERROR(H28/K28,"-") -> 61
B29: 43952 | D29: Ânima | E29: FASEH | F29: Minas Gerais | H29: 144200 | I29: 64700 | J29: 8000 | K29: 1000 | M29: =IFERROR(H29/I29,"-") -> 2.2287481 | N29: =IFERROR(H29/J29,"-") -> 18.025 | O29: =IFERROR(H29/K29,"-") -> 144.2
B30: 43983 | D30: YDUQS | E30: Athenas Grupo Ed. | F30: AC, RO and MT | H30: 120000 | I30: 94500 | J30: 15000 | K30: 9000 | M30: =IFERROR(H30/I30,"-") -> 1.2698413 | N30: =IFERROR(H30/J30,"-") -> 8 | O30: =IFERROR(H30/K30,"-") -> 13.333333
B31: 44013 | D31: Ânima | E31: UniFG | F31: Bahia | H31: 130000 | I31: 59400 | J31: 9200 | K31: 3800 | M31: =IFERROR(H31/I31,"-") -> 2.1885522 | N31: =IFERROR(H31/J31,"-") -> 14.130435 | O31: =IFERROR(H31/K31,"-") -> 34.210526
B32: 44044 | D32: Ser Educacional | E32: FACIMED | F32: Rondônia | H32: 150000 | I32: 55000 | J32: - | K32: 2700 | M32: =IFERROR(H32/I32,"-") -> 2.7272727 | N32: =IFERROR(H32/J32,"-") -> - | O32: =IFERROR(H32/K32,"-") -> 55.555556
B33: 44075 | D33: Ser Educacional | E33: Juazeiro do Norte | F33: Ceará | H33: 24000 | I33: 20000 | J33: 4300 | K33: 2100 | M33: =IFERROR(H33/I33,"-") -> 1.2 | N33: =IFERROR(H33/J33,"-") -> 5.5813953 | O33: =IFERROR(H33/K33,"-") -> 11.428571
B34: 44136 | D34: Ânima | E34: Laureate | F34: Many Locations | H34: 4400000 | I34: 2200000 | J34: 413000 | K34: 251000 | M34: =IFERROR(H34/I34,"-") -> 2 | N34: =IFERROR(H34/J34,"-") -> 10.653753 | O34: =IFERROR(H34/K34,"-") -> 17.52988
B35: 44136 | D35: Farallon | E35: FMU | F35: São Paulo | H35: 500000 | I35: - | J35: 4300 | K35: 55000 | M35: =IFERROR(H35/I35,"-") -> - | N35: =IFERROR(H35/J35,"-") -> 116.27907 | O35: =IFERROR(H35/K35,"-") -> 9.0909091
B36: 44166 | D36: Ser Educacional | E36: UNESC | F36: Rondônia | H36: 120000 | I36: 42000 | J36: - | K36: 2900 | M36: =IFERROR(H36/I36,"-") -> 2.8571429 | N36: =IFERROR(H36/J36,"-") -> - | O36: =IFERROR(H36/K36,"-") -> 41.37931
B37: 44287 | D37: Ânima | E37: Milton Campos | F37: Minas Gerais | H37: 57100 | I37: 20600 | J37: - | K37: 1100 | M37: =IFERROR(H37/I37,"-") -> 2.7718447 | N37: =IFERROR(H37/J37,"-") -> - | O37: =IFERROR(H37/K37,"-") -> 51.909091
B38: 44317 | D38: Afya | E38: Unigranrio | F38: Rio de Janeiro | H38: 700000 | I38: 263100 | J38: - | K38: 24200 | M38: =IFERROR(H38/I38,"-") -> 2.6605853 | N38: =IFERROR(H38/J38,"-") -> - | O38: =IFERROR(H38/K38,"-") -> 28.92562
B39: 44317 | D39: Ser Educacional | E39: FAEL | F39: Paraná | H39: 280000 | I39: 156000 | J39: 20000 | K39: 90000 | M39: =IFERROR(H39/I39,"-") -> 1.7948718 | N39: =IFERROR(H39/J39,"-") -> 14 | O39: =IFERROR(H39/K39,"-") -> 3.1111111
B40: 44378 | D40: Ser Educacional | E40: DOK & CFMV | F40: Rio de Janeiro | H40: 12000 | I40: 5000 | J40: - | K40: 500 | M40: =IFERROR(H40/I40,"-") -> 2.4 | N40: =IFERROR(H40/J40,"-") -> - | O40: =IFERROR(H40/K40,"-") -> 24
B41: 44378 | D41: Cruzeiro do Sul | E41: Moura Lacerda | F41: São Paulo | H41: 54000 | I41: - | J41: - | K41: 3000 | M41: =IFERROR(H41/I41,"-") -> - | N41: =IFERROR(H41/J41,"-") -> - | O41: =IFERROR(H41/K41,"-") -> 18
B42: 44378 | D42: Vitru | E42: Unicesumar | F42: Paraná | H42: 3228000 | I42: 762000 | J42: 260000 | K42: 331000 | M42: =IFERROR(H42/I42,"-") -> 4.2362205 | N42: =IFERROR(H42/J42,"-") -> 12.415385 | O42: =IFERROR(H42/K42,"-") -> 9.7522659
B44: Max | M44: =IFERROR(MAX(M8:M42),"-") -> 4.691358 | N44: =IFERROR(MAX(N8:N42),"-") -> 116.27907 | O44: =IFERROR(MAX(O8:O42),"-") -> 154.28571
...

Sheet DL Model & DCF
B2: Digital Learning Model & DCF
B3: R$ Thousands ('000) Except per Share Data
B5: Digital Learning as % of Ânima's Financials | C5: 0.06951239
B6: WACC | C6: =WACC!C22 -> 0.21386748
B7: 2025 Stub Adjustment | C7: 0
B8: 2026 Stub Adjustment | C8: =YEARFRAC(F72,H72) -> 0.91666667
B9: Terminal Value Approach: | C9: EBITDA Exit Multiple
B10: Enterprise Value | C10: =IF(C9="EBITDA Exit Multiple",L86,C86) -> 637488.11
A14: 1. | B14: DIGITAL LEARNING INCOME STATEMENT | D14: 2022 | E14: 2023 | F14: 2024 | G14: 2025 | H14: 2026 | I14: 2027 | J14: 2028 | K14: 2029 | L14: 2030
B16: Net Revenue | D16: 219396.81 | E16: 273347.16 | F16: 298848.4 | G16: ='Financial Statement Model'!H34 -> 318577.15 | H16: ='Financial Statement Model'!I34 -> 337758.9 | I16: ='Financial Statement Model'!J34 -> 359303.59 | J16: ='Financial Statement Model'!K34 -> 383764.09 | K16: ='Financial Statement Model'!L34 -> 408169.81 | L16: ='Financial Statement Model'!M34 -> 433913.95
B17: Cost of goods sold | D17: -16364.92 | E17: -17461.849 | F17: -20609.408 | G17: =G18-G16 -> -21969.957 | H17: =H18-H16 -> -22279.506 | I17: =I18-I16 -> -22622.742 | J17: =J18-J16 -> -23011.551 | K17: =K18-K16 -> -23250.475 | L17: =L18-L16 -> -23415.19
B18: Gross Profit | D18: =SUM(D16:D17) -> 203031.89 | E18: =SUM(E16:E17) -> 255885.31 | F18: =SUM(F16:F17) -> 278238.99 | G18: =G16*G29 -> 296607.2 | H18: =H16*H29 -> 315479.39 | I18: =I16*I29 -> 336680.85 | J18: =J16*J29 -> 360752.54 | K18: =K16*K29 -> 384919.33 | L18: =L16*L29 -> 410498.76
B19: Selling, general & administrative | D19: -152954.62 | E19: -193270.67 | F19: -167134.54 | G19: =-G16*G30 -> -178084.63 | H19: =-H16*H30 -> -186780.67 | I19: =-I16*I30 -> -196539.06 | J19: =-J16*J30 -> -207616.38 | K19: =-K16*K30 -> -218370.85 | L19: =-L16*L30 -> -229540.48
B20: Other Operating Income (Expenses) | D20: -2331.1516 | E20: -1204.1136 | F20: 3693.1361 | G20: =AVERAGE(D20:F20) -> 52.623616 | H20: =AVERAGE(E20:G20) -> 847.21535 | I20: =AVERAGE(F20:H20) -> 1530.9917 | J20: =AVERAGE(G20:I20) -> 810.27688 | K20: =AVERAGE(H20:J20) -> 1062.828 | L20: =AVERAGE(I20:K20) -> 1134.6988
B21: Operating Profit (EBITDA) | D21: =SUM(D18:D20) -> 47746.115 | E21: =SUM(E18:E20) -> 61410.529 | F21: =SUM(F18:F20) -> 114797.59 | G21: =SUM(G18:G20) -> 118575.19 | H21: =SUM(H18:H20) -> 129545.94 | I21: =SUM(I18:I20) -> 141672.78 | J21: =SUM(J18:J20) -> 153946.45 | K21: =SUM(K18:K20) -> 167611.31 | L21: =SUM(L18:L20) -> 182092.98
B23: Depreciation & amortization | D23: ='Financial Statement Model'!E74*'DL Model & DCF'!$C$5 -> 39020.502 | E23: ='Financial Statement Model'!F74*'DL Model & DCF'!$C$5 -> 38776.236 | F23: ='Financial Statement Model'!G74*'DL Model & DCF'!$C$5 -> 33437.962 | G23: ='Financial Statement Model'!H74*'DL Model & DCF'!$C$5 -> 32787.055 | H23: ='Financial Statement Model'!I74*'DL Model & DCF'!$C$5 -> 31496.214 | I23: ='Financial Statement Model'!J74*'DL Model & DCF'!$C$5 -> 30541.268 | J23: ='Financial Statement Model'!K74*'DL Model & DCF'!$C$5 -> 29884.075 | K23: ='Financial Statement Model'!L74*'DL Model & DCF'!$C$5 -> 29499.355 | L23: ='Financial Statement Model'!M74*'DL Model & DCF'!$C$5 -> 29372.678
B24: EBIT | D24: =D21-D23 -> 8725.6133 | E24: =E21-E23 -> 22634.293 | F24: =F21-F23 -> 81359.63 | G24: =G21-G23 -> 85788.137 | H24: =H21-H23 -> 98049.722 | I24: =I21-I23 -> 111131.51 | J24: =J21-J23 -> 124062.37 | K24: =K21-K23 -> 138111.96 | L24: =L21-L23 -> 152720.3
B27: Income Statement Assumptions
B28: Revenue growth | D28: 0 | E28: =E16/D16-1 -> 0.2459031 | F28: =F16/E16-1 -> 0.0932925 | G28: =G16/F16-1 -> 0.06601592 | H28: =H16/G16-1 -> 0.060210666 | I28: =I16/H16-1 -> 0.063787192 | J28: =J16/I16-1 -> 0.068077544 | K28: =K16/J16-1 -> 0.063595608 | L28: =L16/K16-1 -> 0.063072145
B29: Gross profit margin | D29: =D18/D16 -> 0.92540949 | E29: =E18/E16 -> 0.93611842 | F29: =F18/F16 -> 0.93103725 | G29: =_xlfn.XLOOKUP('Financial Statement Model'!$C$10,'DL Model & DCF'!$B$47:$B$49,'DL Model & DCF'!G47:G49) -> 0.93103725 | H29: =_xlfn.XLOOKUP('Financial Statement Model'!$C$10,'DL Model & DCF'!$B$47:$B$49,'DL Model & DCF'!H47:H49) -> 0.93403725 | I29: =_xlfn.XLOOKUP('Financial Statement Model'!$C$10,'DL Model & DCF'!$B$47:$B$49,'DL Model & DCF'!I47:I49) -> 0.93703725 | J29: =_xlfn.XLOOKUP('Financial Statement Model'!$C$10,'DL Model & DCF'!$B$47:$B$49,'DL Model & DCF'!J47:J49) -> 0.94003725 | K29: =_xlfn.XLOOKUP('Financial Statement Model'!$C$10,'DL Model & DCF'!$B$47:$B$49,'DL Model & DCF'!K47:K49) -> 0.94303725 | L29: =_xlfn.XLOOKUP('Financial Statement Model'!$C$10,'DL Model & DCF'!$B$47:$B$49,'DL Model & DCF'!L47:L49) -> 0.94603725
B30: SG&A % of sales | D30: =-D19/D16 -> 0.69715974 | E30: =-E19/E16 -> 0.70705205 | F30: =-F19/F16 -> 0.55926194 | G30: =_xlfn.XLOOKUP('Financial Statement Model'!$C$10,'DL Model & DCF'!$B$52:$B$54,'DL Model & DCF'!G52:G54) -> 0.559 | H30: =_xlfn.XLOOKUP('Financial Statement Model'!$C$10,'DL Model & DCF'!$B$52:$B$54,'DL Model & DCF'!H52:H54) -> 0.553 | I30: =_xlfn.XLOOKUP('Financial Statement Model'!$C$10,'DL Model & DCF'!$B$52:$B$54,'DL Model & DCF'!I52:I54) -> 0.547 | J30: =_xlfn.XLOOKUP('Financial Statement Model'!$C$10,'DL Model & DCF'!$B$52:$B$54,'DL Model & DCF'!J52:J54) -> 0.541 | K30: =_xlfn.XLOOKUP('Financial Statement Model'!$C$10,'DL Model & DCF'!$B$52:$B$54,'DL Model & DCF'!K52:K54) -> 0.535 | L30: =_xlfn.XLOOKUP('Financial Statement Model'!$C$10,'DL Model & DCF'!$B$52:$B$54,'DL Model & DCF'!L52:L54) -> 0.529
A34: 2. | B34: OPERATING SCENARIOS (ASSUMPTIONS) | D34: 2022 | E34: 2023 | F34: 2024 | G34: 2025 | H34: 2026 | I34: 2027 | J34: 2028 | K34: 2029 | L34: 2030
B36: Digital Learning Net New Students
B37: Bull | G37: ='Financial Statement Model'!H295 -> -6650 | H37: ='Financial Statement Model'!I295 -> -4500 | I37: ='Financial Statement Model'!J295 -> -1800 | J37: ='Financial Statement Model'!K295 -> 1100 | K37: ='Financial Statement Model'!L295 -> 3150 | L37: ='Financial Statement Model'!M295 -> 3150
B38: Target | D38: ='Financial Statement Model'!E296 -> - | E38: ='Financial Statement Model'!F296 -> 13456 | F38: ='Financial Statement Model'!G296 -> -6589 | G38: ='Financial Statement Model'!H296 -> -7000 | H38: ='Financial Statement Model'!I296 -> -5000 | I38: ='Financial Statement Model'!J296 -> -2000 | J38: ='Financial Statement Model'!K296 -> 1000 | K38: ='Financial Statement Model'!L296 -> 3000 | L38: ='Financial Statement Model'!M296 -> 3000
B39: Bear | G39: ='Financial Statement Model'!H297 -> -7450 | H39: ='Financial Statement Model'!I297 -> -5500 | I39: ='Financial Statement Model'!J297 -> -2200 | J39: ='Financial Statement Model'!K297 -> 900 | K39: ='Financial Statement Model'!L297 -> 2800 | L39: ='Financial Statement Model'!M297 -> 2800
B41: Digital Learning Average Anual Ticket Growth Rate
B42: Bull | G42: ='Financial Statement Model'!H300 -> 0.126 | H42: ='Financial Statement Model'!I300 -> 0.105 | I42: ='Financial Statement Model'!J300 -> 0.085 | J42: ='Financial Statement Model'!K300 -> 0.065 | K42: ='Financial Statement Model'!L300 -> 0.045 | L42: ='Financial Statement Model'!M300 -> 0.043
B43: Target | D43: ='Financial Statement Model'!E301 -> - | E43: ='Financial Statement Model'!F301 -> 0.13547494 | F43: ='Financial Statement Model'!G301 -> 0.14289522 | G43: ='Financial Statement Model'!H301 -> 0.12 | H43: ='Financial Statement Model'!I301 -> 0.1 | I43: ='Financial Statement Model'!J301 -> 0.08 | J43: ='Financial Statement Model'!K301 -> 0.06 | K43: ='Financial Statement Model'!L301 -> 0.04 | L43: ='Financial Statement Model'!M301 -> 0.04
B44: Bear | G44: ='Financial Statement Model'!H302 -> 0.113 | H44: ='Financial Statement Model'!I302 -> 0.09 | I44: ='Financial Statement Model'!J302 -> 0.075 | J44: ='Financial Statement Model'!K302 -> 0.055 | K44: ='Financial Statement Model'!L302 -> 0.035 | L44: ='Financial Statement Model'!M302 -> 0.033
B46: Digital Learning Gross Profit Margin
B47: Bull | G47: 0.945 | H47: =G47+0.3% -> 0.948 | I47: =H47+0.3% -> 0.951 | J47: =I47+0.3% -> 0.954 | K47: =J47+0.3% -> 0.957 | L47: =K47+0.3% -> 0.96
B48: Target | D48: =D29 -> 0.92540949 | E48: =E29 -> 0.93611842 | F48: =F29 -> 0.93103725 | G48: 0.93103725 | H48: =G48+0.3% -> 0.93403725 | I48: =H48+0.3% -> 0.93703725 | J48: =I48+0.3% -> 0.94003725 | K48: =J48+0.3% -> 0.94303725 | L48: =K48+0.3% -> 0.94603725
B49: Bear | G49: 0.92 | H49: =G49+0.3% -> 0.923 | I49: =H49+0.3% -> 0.926 | J49: =I49+0.3% -> 0.929 | K49: =J49+0.3% -> 0.932 | L49: =K49+0.3% -> 0.935
B51: Digital Learning SG&A as % of Sales
B52: Bull | G52: 0.545 | H52: =G52-0.6% -> 0.539 | I52: =H52-0.6% -> 0.533 | J52: =I52-0.6% -> 0.527 | K52: =J52-0.6% -> 0.521 | L52: =K52-0.6% -> 0.515
B53: Target | D53: =D30 -> 0.69715974 | E53: =E30 -> 0.70705205 | F53: =F30 -> 0.55926194 | G53: 0.559 | H53: =G53-0.6% -> 0.553 | I53: =H53-0.6% -> 0.547 | J53: =I53-0.6% -> 0.541 | K53: =J53-0.6% -> 0.535 | L53: =K53-0.6% -> 0.529
B54: Bear | G54: 0.57 | H54: =G54-0.6% -> 0.564 | I54: =H54-0.6% -> 0.558 | J54: =I54-0.6% -> 0.552 | K54: =J54-0.6% -> 0.546 | L54: =K54-0.6% -> 0.54
A58: 3. | B58: UNLEVERED FREE CASH FLOWS | D58: 2022 | E58: 2023 | F58: 2024 | G58: 2025 | H58: 2026 | I58: 2027 | J58: 2028 | K58: 2029 | L58: 2030
B60: Tax Rate | D60: ='Financial Statement Model'!E77 -> 0 | E60: ='Financial Statement Model'!F77 -> 0 | F60: ='Financial Statement Model'!G77 -> 0 | G60: ='Financial Statement Model'!H77 -> 0 | H60: ='Financial Statement Model'!I77 -> 0.15 | I60: ='Financial Statement Model'!J77 -> 0.15 | J60: ='Financial Statement Model'!K77 -> 0.15 | K60: ='Financial Statement Model'!L77 -> 0.15 | L60: ='Financial Statement Model'!M77 -> 0.15
...

Sheet DL Trading Comps
B2: Digital Learning Trading Comparables Analysis
B3: R$ Thousands ('000) Except per Share Data
A5: 1. | B5: DIGITAL LEARNING COMPARABLES DATA
I8: Net Revenue | K8: EBITDA | M8: Net Income | O8: EV / Revenue | Q8: EV / EBITDA
B9: Ticker | C9: Company | E9: Enterprise Value | F9: Market Cap. | G9: Price | I9: LTM | K9: LTM | M9: LTM | O9: LTM | Q9: LTM
B10: ='Higher Education Peers Data'!C7 -> ANIM3 | C10: ='Higher Education Peers Data'!C9 -> Ânima | E10: ='Higher Education Peers Data'!C49 -> 6499342.9 | F10: ='Higher Education Peers Data'!C41 -> 2112233.9 | G10: ='Higher Education Peers Data'!C10 -> 5.23 | I10: ='Higher Education Peers Data'!C79 -> 3946759.5 | K10: ='Higher Education Peers Data'!C91 -> 1415835.5 | M10: ='Higher Education Peers Data'!C88 -> 294546.82 | O10: =IFERROR($E10/I10,"-") -> 1.6467542 | Q10: =IFERROR($E10/K10,"-") -> 4.5904647
B11: ='Higher Education Peers Data'!E7 -> COGN3 | C11: ='Higher Education Peers Data'!E9 -> Cogna | E11: ='Higher Education Peers Data'!E49 -> 14950500 | F11: ='Higher Education Peers Data'!E41 -> 8613622.5 | G11: ='Higher Education Peers Data'!E10 -> 4.59 | I11: ='Higher Education Peers Data'!E79 -> 6976160 | K11: ='Higher Education Peers Data'!E91 -> 2248748 | M11: ='Higher Education Peers Data'!E88 -> 1443896 | O11: =IFERROR($E11/I11,"-") -> 2.1430844 | Q11: =IFERROR($E11/K11,"-") -> 6.6483659
B12: ='Higher Education Peers Data'!G7 -> YDUQ3 | C12: ='Higher Education Peers Data'!G9 -> Yduqs | E12: ='Higher Education Peers Data'!G49 -> 8460337.8 | F12: ='Higher Education Peers Data'!G41 -> 4179542.8 | G12: ='Higher Education Peers Data'!G10 -> 14.68 | I12: ='Higher Education Peers Data'!G79 -> 5483298 | K12: ='Higher Education Peers Data'!G91 -> 1702550 | M12: ='Higher Education Peers Data'!G88 -> 243466 | O12: =IFERROR($E12/I12,"-") -> 1.5429287 | Q12: =IFERROR($E12/K12,"-") -> 4.9692155
B13: ='Higher Education Peers Data'!O7 -> VTRU3 | C13: ='Higher Education Peers Data'!O9 -> Vitru | E13: ='Higher Education Peers Data'!O49 -> 3893448 | F13: ='Higher Education Peers Data'!O41 -> 2229158 | G13: ='Higher Education Peers Data'!O10 -> 16.55 | I13: ='Higher Education Peers Data'!O79 -> 2231001 | K13: ='Higher Education Peers Data'!O91 -> 715170 | M13: ='Higher Education Peers Data'!O88 -> 469944 | O13: =IFERROR($E13/I13,"-") -> 1.7451575 | Q13: =IFERROR($E13/K13,"-") -> 5.4440875
B15: Max | O15: =IFERROR(MAX(O10:O13),"-") -> 2.1430844 | Q15: =IFERROR(MAX(Q10:Q13),"-") -> 6.6483659
B16: 75th Percentile | O16: =IFERROR(_xlfn.QUARTILE.INC(O10:O13,3),"-") -> 1.8446392 | Q16: =IFERROR(_xlfn.QUARTILE.INC(Q10:Q13,3),"-") -> 5.7451571
B17: Median | O17: =IFERROR(MEDIAN(O10:O13),"-") -> 1.6959558 | Q17: =IFERROR(MEDIAN(Q10:Q13),"-") -> 5.2066515
B18: 25th Percentile | O18: =IFERROR(_xlfn.QUARTILE.INC(O10:O13,1),"-") -> 1.6207978 | Q18: =IFERROR(_xlfn.QUARTILE.INC(Q10:Q13,1),"-") -> 4.8745278
B19: Min | O19: =IFERROR(MIN(O10:O13),"-") -> 1.5429287 | Q19: =IFERROR(MIN(Q10:Q13),"-") -> 4.5904647
O22: Revenue LTM | Q22: EBITDA LTM
E23: 25th Percentile | F23: Bar | G23: 75th Percentile | M23: Digital Learning Data | O23: 247508.18 | Q23: 112594.89
C24: EV / LTM Revenue | E24: =O32 -> 401160.72 | F24: =G24-E24 -> 55402.565 | G24: =O30 -> 456563.28
C25: EV / LTM EBITDA | E25: =Q32 -> 548846.92 | F25: =G25-E25 -> 98028.41 | G25: =Q30 -> 646875.33
O27: EV / Revenue | Q27: EV / EBITDA
M28: Enterprise Value | O28: LTM | Q28: LTM
M29: Max | O29: =O15*$O$23 -> 530430.91 | Q29: =Q15*$Q$23 -> 748572.03
M30: 75th Percentile | O30: =O16*$O$23 -> 456563.28 | Q30: =Q16*$Q$23 -> 646875.33
M31: Median | O31: =O17*$O$23 -> 419762.94 | Q31: =Q17*$Q$23 -> 586242.35
M32: 25th Percentile | O32: =O18*$O$23 -> 401160.72 | Q32: =Q18*$Q$23 -> 548846.92
M33: Min | O33: =O19*$O$23 -> 381887.47 | Q33: =Q19*$Q$23 -> 516862.86

Sheet DL Transaction Comps
B2: Digital Learning Trading Comparables Analysis
B3: R$ Thousands ('000) Except per Share Data
A5: 1. | B5: DIGITAL LEARNING COMPARABLES DATA
